Workbook

Sheet Trial 1
A1: Trial 1 — Answer Sheet
A3: NC 1back
A4: 1-back | 10 stimuli | valid responses: 9
A5: # | B5: Position | C5: 1 step(s) ago | D5: Correct answer | E5: Response | F5: O / X
A6: 1 | B6: 6 | C6: - | D6: -
A7: 2 | B7: 5 | C7: 6 | D7: いいえ
A8: 3 | B8: 5 | C8: 5 | D8: はい
A9: 4 | B9: 2 | C9: 5 | D9: いいえ
A10: 5 | B10: 5 | C10: 2 | D10: いいえ
A11: 6 | B11: 5 | C11: 5 | D11: はい
A12: 7 | B12: 5 | C12: 5 | D12: はい
A13: 8 | B13: 4 | C13: 5 | D13: いいえ
A14: 9 | B14: 1 | C14: 4 | D14: いいえ
A15: 10 | B15: 6 | C15: 1 | D15: いいえ
A16: Accuracy: | D16: / 9 | F16: %
A18: NC 2back
A19: 2-back | 10 stimuli | valid responses: 8
A20: # | B20: Position | C20: 2 step(s) ago | D20: Correct answer | E20: Response | F20: O / X
A21: 1 | B21: 3 | C21: - | D21: -
A22: 2 | B22: 3 | C22: - | D22: -
A23: 3 | B23: 5 | C23: 3 | D23: いいえ
A24: 4 | B24: 3 | C24: 3 | D24: はい
A25: 5 | B25: 6 | C25: 5 | D25: いいえ
A26: 6 | B26: 2 | C26: 3 | D26: いいえ
A27: 7 | B27: 5 | C27: 6 | D27: いいえ
A28: 8 | B28: 2 | C28: 2 | D28: はい
A29: 9 | B29: 3 | C29: 5 | D29: いいえ
A30: 10 | B30: 1 | C30: 2 | D30: いいえ
A31: Accuracy: | D31: / 8 | F31: %
A33: NC 3back
A34: 3-back | 10 stimuli | valid responses: 7
A35: # | B35: Position | C35: 3 step(s) ago | D35: Correct answer | E35: Response | F35: O / X
A36: 1 | B36: 5 | C36: - | D36: -
A37: 2 | B37: 2 | C37: - | D37: -
A38: 3 | B38: 1 | C38: - | D38: -
A39: 4 | B39: 5 | C39: 5 | D39: はい
A40: 5 | B40: 5 | C40: 2 | D40: いいえ
A41: 6 | B41: 2 | C41: 1 | D41: いいえ
A42: 7 | B42: 3 | C42: 5 | D42: いいえ
A43: 8 | B43: 1 | C43: 5 | D43: いいえ
...

Sheet Trial 2
A1: Trial 2 — Answer Sheet
A3: NC 1back
A4: 1-back | 10 stimuli | valid responses: 9
A5: # | B5: Position | C5: 1 step(s) ago | D5: Correct answer | E5: Response | F5: O / X
A6: 1 | B6: 5 | C6: - | D6: -
A7: 2 | B7: 6 | C7: 5 | D7: いいえ
A8: 3 | B8: 6 | C8: 6 | D8: はい
A9: 4 | B9: 5 | C9: 6 | D9: いいえ
A10: 5 | B10: 4 | C10: 5 | D10: いいえ
A11: 6 | B11: 4 | C11: 4 | D11: はい
A12: 7 | B12: 2 | C12: 4 | D12: いいえ
A13: 8 | B13: 4 | C13: 2 | D13: いいえ
A14: 9 | B14: 4 | C14: 4 | D14: はい
A15: 10 | B15: 6 | C15: 4 | D15: いいえ
A16: Accuracy: | D16: / 9 | F16: %
A18: NC 2back
A19: 2-back | 10 stimuli | valid responses: 8
A20: # | B20: Position | C20: 2 step(s) ago | D20: Correct answer | E20: Response | F20: O / X
A21: 1 | B21: 3 | C21: - | D21: -
A22: 2 | B22: 2 | C22: - | D22: -
A23: 3 | B23: 5 | C23: 3 | D23: いいえ
A24: 4 | B24: 1 | C24: 2 | D24: いいえ
A25: 5 | B25: 1 | C25: 5 | D25: いいえ
A26: 6 | B26: 3 | C26: 1 | D26: いいえ
A27: 7 | B27: 1 | C27: 1 | D27: はい
A28: 8 | B28: 4 | C28: 3 | D28: いいえ
A29: 9 | B29: 1 | C29: 1 | D29: はい
A30: 10 | B30: 4 | C30: 4 | D30: はい
A31: Accuracy: | D31: / 8 | F31: %
A33: NC 3back
A34: 3-back | 10 stimuli | valid responses: 7
A35: # | B35: Position | C35: 3 step(s) ago | D35: Correct answer | E35: Response | F35: O / X
A36: 1 | B36: 2 | C36: - | D36: -
A37: 2 | B37: 6 | C37: - | D37: -
A38: 3 | B38: 2 | C38: - | D38: -
A39: 4 | B39: 6 | C39: 2 | D39: いいえ
A40: 5 | B40: 1 | C40: 6 | D40: いいえ
A41: 6 | B41: 6 | C41: 2 | D41: いいえ
A42: 7 | B42: 4 | C42: 6 | D42: いいえ
A43: 8 | B43: 2 | C43: 1 | D43: いいえ
...

Sheet Trial 3
A1: Trial 3 — Answer Sheet
A3: NC 1back
A4: 1-back | 10 stimuli | valid responses: 9
A5: # | B5: Position | C5: 1 step(s) ago | D5: Correct answer | E5: Response | F5: O / X
A6: 1 | B6: 1 | C6: - | D6: -
A7: 2 | B7: 1 | C7: 1 | D7: はい
A8: 3 | B8: 1 | C8: 1 | D8: はい
A9: 4 | B9: 5 | C9: 1 | D9: いいえ
A10: 5 | B10: 5 | C10: 5 | D10: はい
A11: 6 | B11: 5 | C11: 5 | D11: はい
A12: 7 | B12: 4 | C12: 5 | D12: いいえ
A13: 8 | B13: 6 | C13: 4 | D13: いいえ
A14: 9 | B14: 5 | C14: 6 | D14: いいえ
A15: 10 | B15: 5 | C15: 5 | D15: はい
A16: Accuracy: | D16: / 9 | F16: %
A18: NC 2back
A19: 2-back | 10 stimuli | valid responses: 8
A20: # | B20: Position | C20: 2 step(s) ago | D20: Correct answer | E20: Response | F20: O / X
A21: 1 | B21: 4 | C21: - | D21: -
A22: 2 | B22: 1 | C22: - | D22: -
A23: 3 | B23: 1 | C23: 4 | D23: いいえ
A24: 4 | B24: 1 | C24: 1 | D24: はい
A25: 5 | B25: 1 | C25: 1 | D25: はい
A26: 6 | B26: 2 | C26: 1 | D26: いいえ
A27: 7 | B27: 5 | C27: 1 | D27: いいえ
A28: 8 | B28: 1 | C28: 2 | D28: いいえ
A29: 9 | B29: 5 | C29: 5 | D29: はい
A30: 10 | B30: 1 | C30: 1 | D30: はい
A31: Accuracy: | D31: / 8 | F31: %
A33: NC 3back
A34: 3-back | 10 stimuli | valid responses: 7
A35: # | B35: Position | C35: 3 step(s) ago | D35: Correct answer | E35: Response | F35: O / X
A36: 1 | B36: 5 | C36: - | D36: -
A37: 2 | B37: 2 | C37: - | D37: -
A38: 3 | B38: 4 | C38: - | D38: -
A39: 4 | B39: 6 | C39: 5 | D39: いいえ
A40: 5 | B40: 2 | C40: 2 | D40: はい
A41: 6 | B41: 1 | C41: 4 | D41: いいえ
A42: 7 | B42: 6 | C42: 6 | D42: はい
A43: 8 | B43: 5 | C43: 2 | D43: いいえ
...

Sheet Trial 4
A1: Trial 4 — Answer Sheet
A3: NC 1back
A4: 1-back | 10 stimuli | valid responses: 9
A5: # | B5: Position | C5: 1 step(s) ago | D5: Correct answer | E5: Response | F5: O / X
A6: 1 | B6: 5 | C6: - | D6: -
A7: 2 | B7: 5 | C7: 5 | D7: はい
A8: 3 | B8: 5 | C8: 5 | D8: はい
A9: 4 | B9: 6 | C9: 5 | D9: いいえ
A10: 5 | B10: 5 | C10: 6 | D10: いいえ
A11: 6 | B11: 2 | C11: 5 | D11: いいえ
A12: 7 | B12: 4 | C12: 2 | D12: いいえ
A13: 8 | B13: 3 | C13: 4 | D13: いいえ
A14: 9 | B14: 2 | C14: 3 | D14: いいえ
A15: 10 | B15: 3 | C15: 2 | D15: いいえ
A16: Accuracy: | D16: / 9 | F16: %
A18: NC 2back
A19: 2-back | 10 stimuli | valid responses: 8
A20: # | B20: Position | C20: 2 step(s) ago | D20: Correct answer | E20: Response | F20: O / X
A21: 1 | B21: 5 | C21: - | D21: -
A22: 2 | B22: 2 | C22: - | D22: -
A23: 3 | B23: 1 | C23: 5 | D23: いいえ
A24: 4 | B24: 5 | C24: 2 | D24: いいえ
A25: 5 | B25: 1 | C25: 1 | D25: はい
A26: 6 | B26: 3 | C26: 5 | D26: いいえ
A27: 7 | B27: 4 | C27: 1 | D27: いいえ
A28: 8 | B28: 1 | C28: 3 | D28: いいえ
A29: 9 | B29: 2 | C29: 4 | D29: いいえ
A30: 10 | B30: 4 | C30: 1 | D30: いいえ
A31: Accuracy: | D31: / 8 | F31: %
A33: NC 3back
A34: 3-back | 10 stimuli | valid responses: 7
A35: # | B35: Position | C35: 3 step(s) ago | D35: Correct answer | E35: Response | F35: O / X
A36: 1 | B36: 4 | C36: - | D36: -
A37: 2 | B37: 5 | C37: - | D37: -
A38: 3 | B38: 1 | C38: - | D38: -
A39: 4 | B39: 2 | C39: 4 | D39: いいえ
A40: 5 | B40: 3 | C40: 5 | D40: いいえ
A41: 6 | B41: 1 | C41: 1 | D41: はい
A42: 7 | B42: 2 | C42: 2 | D42: はい
A43: 8 | B43: 3 | C43: 3 | D43: はい
...

Sheet Trial 5
A1: Trial 5 — Answer Sheet
A3: NC 1back
A4: 1-back | 10 stimuli | valid responses: 9
A5: # | B5: Position | C5: 1 step(s) ago | D5: Correct answer | E5: Response | F5: O / X
A6: 1 | B6: 4 | C6: - | D6: -
A7: 2 | B7: 5 | C7: 4 | D7: いいえ
A8: 3 | B8: 1 | C8: 5 | D8: いいえ
A9: 4 | B9: 1 | C9: 1 | D9: はい
A10: 5 | B10: 1 | C10: 1 | D10: はい
A11: 6 | B11: 6 | C11: 1 | D11: いいえ
A12: 7 | B12: 5 | C12: 6 | D12: いいえ
A13: 8 | B13: 5 | C13: 5 | D13: はい
A14: 9 | B14: 4 | C14: 5 | D14: いいえ
A15: 10 | B15: 4 | C15: 4 | D15: はい
A16: Accuracy: | D16: / 9 | F16: %
A18: NC 2back
A19: 2-back | 10 stimuli | valid responses: 8
A20: # | B20: Position | C20: 2 step(s) ago | D20: Correct answer | E20: Response | F20: O / X
A21: 1 | B21: 1 | C21: - | D21: -
A22: 2 | B22: 1 | C22: - | D22: -
A23: 3 | B23: 2 | C23: 1 | D23: いいえ
A24: 4 | B24: 5 | C24: 1 | D24: いいえ
A25: 5 | B25: 4 | C25: 2 | D25: いいえ
A26: 6 | B26: 2 | C26: 5 | D26: いいえ
A27: 7 | B27: 4 | C27: 4 | D27: はい
A28: 8 | B28: 3 | C28: 2 | D28: いいえ
A29: 9 | B29: 4 | C29: 4 | D29: はい
A30: 10 | B30: 5 | C30: 3 | D30: いいえ
A31: Accuracy: | D31: / 8 | F31: %
A33: NC 3back
A34: 3-back | 10 stimuli | valid responses: 7
A35: # | B35: Position | C35: 3 step(s) ago | D35: Correct answer | E35: Response | F35: O / X
A36: 1 | B36: 4 | C36: - | D36: -
A37: 2 | B37: 5 | C37: - | D37: -
A38: 3 | B38: 1 | C38: - | D38: -
A39: 4 | B39: 2 | C39: 4 | D39: いいえ
A40: 5 | B40: 2 | C40: 5 | D40: いいえ
A41: 6 | B41: 1 | C41: 1 | D41: はい
A42: 7 | B42: 3 | C42: 2 | D42: いいえ
A43: 8 | B43: 2 | C43: 2 | D43: はい
...

Sheet 総合正答率
B1: NC-1back | C1: NC-2back | D1: NC-3back | E1: VLTC-1back | F1: VLTC-2back | G1: VLTC-3back
A2: 1trial | B2: ='Trial 1'!C16/9 -> 0 | C2: ='Trial 1'!C31/8 -> 0 | D2: ='Trial 1'!C46/7 -> 0 | E2: ='Trial 1'!C61/9 -> 0 | F2: ='Trial 1'!C76/8 -> 0 | G2: ='Trial 1'!C91/7 -> 0
A3: 2trial | B3: ='Trial 2'!C16/9 -> 0 | C3: ='Trial 2'!C31/8 -> 0 | D3: ='Trial 2'!C46/7 -> 0 | E3: ='Trial 2'!C61/9 -> 0 | F3: ='Trial 2'!C76/8 -> 0 | G3: ='Trial 2'!C91/7 -> 0
A4: 3trial | B4: ='Trial 3'!C16/9 -> 0 | C4: ='Trial 3'!C31/8 -> 0 | D4: ='Trial 3'!C46/7 -> 0 | E4: ='Trial 3'!C61/9 -> 0 | F4: ='Trial 3'!C76/8 -> 0 | G4: ='Trial 3'!C91/7 -> 0
A5: 4trial | B5: ='Trial 4'!C16/9 -> 0 | C5: ='Trial 4'!C31/8 -> 0 | D5: ='Trial 4'!C46/7 -> 0 | E5: ='Trial 4'!C61/9 -> 0 | F5: ='Trial 4'!C76/8 -> 0 | G5: ='Trial 4'!C91/7 -> 0
A6: 5trial | B6: ='Trial 5'!C16/9 -> 0 | C6: ='Trial 5'!C31/8 -> 0 | D6: ='Trial 5'!C46/7 -> 0 | E6: ='Trial 5'!C61/9 -> 0 | F6: ='Trial 5'!C76/8 -> 0 | G6: ='Trial 5'!C91/7 -> 0
A7: 全体 | B7: =AVERAGE(B2:B6) -> 0 | C7: =AVERAGE(C2:C6) -> 0 | D7: =AVERAGE(D2:D6) -> 0 | E7: =AVERAGE(E2:E6) -> 0 | F7: =AVERAGE(F2:F6) -> 0 | G7: =AVERAGE(G2:G6) -> 0
